Workbook

Sheet Summary
A1: Hindustan Aeronautics Ltd (NSE: HAL | BSE: 541154) - Equity Research Model
A2: Independent equity research - educational / portfolio project. Not investment advice. Valuation date 10-Oct-2026.
A4: Key outputs | B4: Value
A5: Rating | B5: =Valuation!B15 -> HOLD
A6: CMP (Rs, 9-Oct-2026 close) | B6: =Assumptions!B4 -> 4655.6
A7: 12-month target price (Rs) | B7: =Valuation!B9 -> 4150
A8: Upside / (downside) | B8: =Valuation!C9 -> -0.1086004
A9: Market cap (Rs Cr) | B9: =Assumptions!B6 -> 311366.53
A10: DCF value today (Rs/share) | B10: =DCF!B24 -> 2434.9832
A11: Comps value (Rs/share) | B11: =Comps!C24 -> 5056.3613
A12: DCF weight / Comps weight | B12: =TEXT(Valuation!D5,"0%")&" / "&TEXT(Valuation!D6,"0%") -> 50% / 50%
A13: WACC (cost of equity) | B13: =Assumptions!B22 -> 0.1175
A14: Terminal growth | B14: =Assumptions!B23 -> 0.05
A15: Market-implied cost of equity (reverse DCF) | B15: =DCF!B48 -> 0.083
A16: Market EV / FY27E EBITDA | B16: =DCF!B28 -> 24.651011
A17: P/E on FY27E EPS | B17: =DCF!B30 -> 31.486697
A18: P/E on core earnings (ex treasury income) | B18: =Comps!C28 -> 49.229855
A19: Order book / FY26 revenue | B19: =Historical!D66 -> 7.6925262
A22: Financial summary (Rs Cr) | B22: FY24 | C22: FY25 | D22: FY26 | E22: FY27E | F22: FY28E
A23: Revenue | B23: =Historical!F5 -> 30381 | C23: =Historical!G5 -> 30981 | D23: =Historical!H5 -> 33089 | E23: =Forecast!C7 -> 36728.79 | F23: =Forecast!D7 -> 41503.533
A24: EBITDA | B24: =Historical!F6 -> 9752 | C24: =Historical!G6 -> 9621 | D24: =Historical!H6 -> 9788 | E24: =Forecast!C9 -> 10834.993 | F24: =Forecast!D9 -> 12451.06
A25: Net profit | B25: =Historical!F12 -> 7621 | C25: =Historical!G12 -> 8364 | D25: =Historical!H12 -> 9116 | E25: =Forecast!C22 -> 9888.8279 | F25: =Forecast!D22 -> 11096.451
A26: EBITDA margin | B26: =Historical!F44 -> 0.32099009 | C26: =Historical!G44 -> 0.31054517 | D26: =Historical!H44 -> 0.29580827 | E26: =Forecast!C8 -> 0.295 | F26: =Forecast!D8 -> 0.3
A27: EPS (Rs) | B27: =Historical!F13 -> 113.96 | C27: =Historical!G13 -> 125.07 | D27: =Historical!H13 -> 136.3 | E27: =Forecast!C23 -> 147.85927 | F27: =Forecast!D23 -> 165.91583
A28: Other income % of PBT | B28: =Historical!F47 -> 0.18806846 | C28: =Historical!G47 -> 0.23999264 | D28: =Historical!H47 -> 0.30801514 | E28: =Forecast!C27 -> 0.2952362 | F28: =Forecast!D27 -> 0.27626104
A29: CFO / EBITDA | B29: =Historical!F52 -> 0.84321165 | C29: =Historical!G52 -> 1.4180439 | D29: =Historical!H52 -> 1.1142215
A30: Free cash flow (reported) | B30: =Historical!F33 -> 6476 | C30: =Historical!G33 -> 11890 | D30: =Historical!H33 -> 8438
A32: Sheets: Historical | Assumptions | Forecast | DCF | Comps | Valuation | MonteCarlo (static) | Scenarios (static) | Notes

Sheet Historical
A1: Hindustan Aeronautics Ltd (HAL) - Historical Financials, Consolidated (Rs Cr)
A2: Source: Screener.in consolidated statements (company filings), retrieved 10-Oct-2026. Blue = hardcoded input from source; black = formula. FY ends 31-Mar.
A4: Rs Cr | B4: FY20 | C4: FY21 | D4: FY22 | E4: FY23 | F4: FY24 | G4: FY25 | H4: FY26
A5: Revenue from operations | B5: 21445 | C5: 22755 | D5: 24620 | E5: 26927 | F5: 30381 | G5: 30981 | H5: 33089
A6: Operating profit (EBITDA) | B6: 4914 | C6: 5357 | D6: 5415 | E6: 6686 | F6: 9752 | G6: 9621 | H6: 9788
A7: Other income | B7: 423 | C7: 365 | D7: 985 | E7: 1673 | F7: 1923 | G7: 2608 | H7: 3743
A8: Interest | B8: 360 | C8: 267 | D8: 65 | E8: 64 | F8: 43 | G8: 22 | H8: 24
A9: Depreciation | B9: 999 | C9: 1178 | D9: 1111 | E9: 1785 | F9: 1407 | G9: 1340 | H9: 1355
A10: Profit before tax | B10: 3979 | C10: 4277 | D10: 5225 | E10: 6510 | F10: 10225 | G10: 10867 | H10: 12152
A11: Tax rate (reported) | B11: 0.28 | C11: 0.24 | D11: 0.03 | E11: 0.1 | F11: 0.25 | G11: 0.23 | H11: 0.25
A12: Net profit (consolidated) | B12: 2883 | C12: 3239 | D12: 5080 | E12: 5828 | F12: 7621 | G12: 8364 | H12: 9116
A13: EPS (Rs, post-split) | B13: 43.1 | C13: 48.44 | D13: 75.96 | E13: 87.14 | F13: 113.96 | G13: 125.07 | H13: 136.3
A14: Dividend payout % | B14: 0.39 | C14: 0.31 | D14: 0.26 | E14: 0.32 | F14: 0.31 | G14: 0.32 | H14: 0.33
A16: Balance sheet (Rs Cr)
A17: Equity capital | B17: 334 | C17: 334 | D17: 334 | E17: 334 | F17: 334 | G17: 334 | H17: 334
A18: Reserves | B18: 12914 | C18: 15078 | D18: 18979 | E18: 23238 | F18: 28804 | G18: 34647 | H18: 40707
A19: Borrowings | B19: 5927 | C19: 51 | D19: 49 | E19: 52 | F19: 50 | G19: 51 | H19: 66
A20: Other liabilities (incl. customer advances) | B20: 35027 | C20: 37815 | D20: 40892 | E20: 45652 | F20: 51723 | G20: 73665 | H20: 93288
A21: Total liabilities | B21: 54203 | C21: 53278 | D21: 60254 | E21: 69276 | F21: 80911 | G21: 108698 | H21: 134395
A22: Fixed assets | B22: 7357 | C22: 7491 | D22: 6766 | E22: 6834 | F22: 6737 | G22: 6671 | H22: 7293
A23: CWIP | B23: 2043 | C23: 2078 | D23: 2473 | E23: 1885 | F23: 2493 | G23: 3098 | H23: 3313
A24: Investments | B24: 991 | C24: 1056 | D24: 1363 | E24: 1458 | F24: 1591 | G24: 1754 | H24: 1914
A25: Other assets (incl. inventory, cash/deposits) | B25: 43812 | C25: 42654 | D25: 49653 | E25: 59099 | F25: 70089 | G25: 97176 | H25: 121875
A26: Total assets | B26: 54203 | C26: 53278 | D26: 60254 | E26: 69276 | F26: 80911 | G26: 108698 | H26: 134395
A28: Cash flow (Rs Cr)
A29: Cash from operations (CFO) | B29: 1527 | C29: 15263 | D29: 10173 | E29: 8830 | F29: 8223 | G29: 13643 | H29: 10906
A30: Cash from investing | B30: -1339 | C30: -1271 | D30: -12785 | E30: -5728 | F30: -6410 | G30: -10771 | H30: -8337
A31: Cash from financing | B31: 64 | C31: -7125 | D31: -1464 | E31: -1731 | F31: -1999 | G31: -2579 | H31: -3350
A32: Net cash flow | B32: 252 | C32: 6867 | D32: -4076 | E32: 1370 | F32: -186 | G32: 294 | H32: -781
A33: Free cash flow (reported, CFO - capex) | B33: 148 | C33: 13947 | D33: 8676 | E33: 7054 | F33: 6476 | G33: 11890 | H33: 8438
A35: Working-capital ratios (days) and returns
A36: Debtor days | B36: 191 | C36: 90 | D36: 69 | E36: 64 | F36: 55 | G36: 55 | H36: 45
A37: Inventory days | B37: 815 | C37: 605 | D37: 607 | E37: 527 | F37: 544 | G37: 736 | H37: 859
A38: Payable days | B38: 163 | C38: 76 | D38: 96 | E38: 116 | F38: 116 | G38: 156 | H38: 116
A39: Cash conversion cycle (days) | B39: 843 | C39: 620 | D39: 580 | E39: 475 | F39: 484 | G39: 634 | H39: 788
A40: ROCE (reported) | B40: 0.24 | C40: 0.26 | D40: 0.3 | E40: 0.31 | F40: 0.39 | G40: 0.34 | H40: 0.32
A42: Derived metrics (formulas)
A43: Revenue growth | C43: =C5/B5-1 -> 0.0610865 | D43: =D5/C5-1 -> 0.081960009 | E43: =E5/D5-1 -> 0.093704305 | F43: =F5/E5-1 -> 0.12827274 | G43: =G5/F5-1 -> 0.019749185 | H43: =H5/G5-1 -> 0.068041703
A44: EBITDA margin | B44: =B6/B5 -> 0.22914432 | C44: =C6/C5 -> 0.23542079 | D44: =D6/D5 -> 0.21994314 | E44: =E6/E5 -> 0.24830096 | F44: =F6/F5 -> 0.32099009 | G44: =G6/G5 -> 0.31054517 | H44: =H6/H5 -> 0.29580827
A45: EBITDA growth | C45: =C6/B6-1 -> 0.09015059 | D45: =D6/C6-1 -> 0.010826955 | E45: =E6/D6-1 -> 0.23471837 | F45: =F6/E6-1 -> 0.45857015 | G45: =G6/F6-1 -> -0.013433142 | H45: =H6/G6-1 -> 0.017357863
...

Sheet Assumptions
A1: Assumptions & Inputs
A2: Blue = input; yellow fill = key judgement. Change here and every sheet recalculates.
A3: Market data (as of 10-Oct-2026) | B3: Value | C3: Source / note
A4: CMP (Rs) - NSE close 9-Oct-2026 | B4: 4655.6 | C4: NSE close 9-Oct-2026 (Screener/Kotak Neo)
A5: Shares outstanding (Cr) | B5: 66.88 | C5: Equity capital Rs 334 Cr / face value Rs 5
A6: Market cap (Rs Cr) | B6: =B4*B5 -> 311366.53 | C6: Formula
A7: Bank deposits (Rs Cr, FY26) | B7: 42425 | C7: FY26 standalone balance sheet (non-cash bank deposits)
A8: Investments (Rs Cr, FY26) | B8: =Historical!H24 -> 1914 | C8: Consolidated balance sheet
A9: Borrowings (Rs Cr, FY26) | B9: =Historical!H19 -> 66 | C9: Consolidated balance sheet
A10: FY26 dividend per share (Rs) | B10: 45 | C10: Rs 35 interim + Rs 10 final
A11: Dividend yield | B11: =B10/B4 -> 0.0096657788 | C11: Formula
A12: Days from 31-Mar-2026 to valuation date (10-Oct-2026) | B12: 193 | C12: Calendar days
A13: Year fraction | B13: =B12/365 -> 0.52876712 | C13: Roll-forward of DCF value from balance-sheet date
A15: Cost of capital | B15: Value | C15: Source / note
A16: Risk-free rate (India 10Y G-Sec) | B16: 0.07 | C16: ~7.0-7.2% late Sep 2026 (Trading Economics)
A17: Equity beta | B17: 0.95 | C17: TradingView (HAL) ~0.95
A18: Equity risk premium | B18: 0.05 | C18: Analyst judgement: premium over INR G-Sec
A19: Cost of equity (CAPM) | B19: =B16+B17*B18 -> 0.1175
A20: WACC (debt is ~0.0% of capital, so WACC = Ke) | B20: =B19 -> 0.1175
A21: WACC overlay (+/- pp, scenario lever) | B21: 0
A22: WACC used | B22: =B20+B21 -> 0.1175
A23: Terminal growth (g) | B23: 0.05 | C23: Below long-run nominal GDP (~9-10%)
A24: Credit given to cash & investments in equity bridge | B24: 0.5 | C24: Judgement: ~half. Non-current advances (Rs 44.7k Cr) ~ deposits (Rs 42.4k Cr); cash is customer-funded
A26: Scenario overlays (0 = base case) | B26: Value | C26: Note
A27: Revenue growth overlay, FY27E-FY31E (pp per year) | B27: 0
A28: EBITDA margin overlay, all years (pp) | B28: 0
A29: Dividend payout ratio (for DPS forecast) | B29: 0.33
A31: Forecast drivers (base case) | B31: FY27E | C31: FY28E | D31: FY29E | E31: FY30E | F31: FY31E | G31: FY32E | H31: FY33E | I31: FY34E | J31: FY35E | K31: FY36E
A32: Revenue growth | B32: 0.11 | C32: 0.13 | D32: 0.13 | E32: 0.11 | F32: 0.1 | G32: 0.09 | H32: 0.08 | I32: 0.07 | J32: 0.065 | K32: 0.06 | L32: FY27: guidance 10-12% (Q1 +14%); FY28-29: Tejas Mk1A/HTT-40 ramp; fade to 6% by FY36
A33: EBITDA margin | B33: 0.295 | C33: 0.3 | D33: 0.3 | E33: 0.3 | F33: 0.3 | G33: 0.3 | H33: 0.3 | I33: 0.3 | J33: 0.3 | K33: 0.3 | L33: FY26: 29.6%; guidance FY27 30-31%, Q1 FY27 27.7%; base is below guidance
A34: D&A % of revenue | B34: 0.042 | C34: 0.042 | D34: 0.042 | E34: 0.042 | F34: 0.042 | G34: 0.042 | H34: 0.042 | I34: 0.042 | J34: 0.042 | K34: 0.042 | L34: FY26: 4.1%
A35: Tax rate on EBIT | B35: 0.25 | C35: 0.25 | D35: 0.25 | E35: 0.25 | F35: 0.25 | G35: 0.25 | H35: 0.25 | I35: 0.25 | J35: 0.25 | K35: 0.25 | L35: Statutory ~25%
A36: Capex % of revenue | B36: 0.075 | C36: 0.075 | D36: 0.07 | E36: 0.065 | F36: 0.06 | G36: 0.055 | H36: 0.055 | I36: 0.055 | J36: 0.055 | K36: 0.055 | L36: FY26: 7.5%; mgmt flags large capex through FY30
A37: Change in NWC, % of incremental revenue | B37: 0.1 | C37: 0.1 | D37: 0.1 | E37: 0.1 | F37: 0.1 | G37: 0.1 | H37: 0.1 | I37: 0.1 | J37: 0.1 | K37: 0.1 | L37: Modest drag; advances unwind handled via cash haircut
A38: Treasury (other) income growth | B38: 0.04 | C38: 0.05 | D38: 0.05 | E38: 0.05 | F38: 0.05 | G38: 0.05 | H38: 0.05 | I38: 0.05 | J38: 0.05 | K38: 0.05 | L38: TTM Rs 3,897 Cr vs FY26 Rs 3,743 Cr (+4%)

Sheet Forecast
A1: Forecast & Free Cash Flow to Firm (Rs Cr) - Base case with scenario overlays
A2: FCFF excludes treasury income (valued via the cash credit in the equity bridge). Year index 1 = FY27E.
A4: Rs Cr | B4: FY26A | C4: FY27E | D4: FY28E | E4: FY29E | F4: FY30E | G4: FY31E | H4: FY32E | I4: FY33E | J4: FY34E | K4: FY35E | L4: FY36E
A5: Year index | C5: 1 | D5: 2 | E5: 3 | F5: 4 | G5: 5 | H5: 6 | I5: 7 | J5: 8 | K5: 9 | L5: 10
A6: Revenue growth (incl. overlay) | B6: =Historical!H43 -> 0.068041703 | C6: =Assumptions!B32+IF(C$5<=5,Assumptions!$B$27,0) -> 0.11 | D6: =Assumptions!C32+IF(D$5<=5,Assumptions!$B$27,0) -> 0.13 | E6: =Assumptions!D32+IF(E$5<=5,Assumptions!$B$27,0) -> 0.13 | F6: =Assumptions!E32+IF(F$5<=5,Assumptions!$B$27,0) -> 0.11 | G6: =Assumptions!F32+IF(G$5<=5,Assumptions!$B$27,0) -> 0.1 | H6: =Assumptions!G32+IF(H$5<=5,Assumptions!$B$27,0) -> 0.09 | I6: =Assumptions!H32+IF(I$5<=5,Assumptions!$B$27,0) -> 0.08 | J6: =Assumptions!I32+IF(J$5<=5,Assumptions!$B$27,0) -> 0.07 | ... L6: =Assumptions!K32+IF(L$5<=5,Assumptions!$B$27,0) -> 0.06
A7: Revenue | B7: =Historical!H5 -> 33089 | C7: =B7*(1+C6) -> 36728.79 | D7: =C7*(1+D6) -> 41503.533 | E7: =D7*(1+E6) -> 46898.992 | F7: =E7*(1+F6) -> 52057.881 | G7: =F7*(1+G6) -> 57263.669 | H7: =G7*(1+H6) -> 62417.399 | I7: =H7*(1+I6) -> 67410.791 | J7: =I7*(1+J6) -> 72129.547 | ... L7: =K7*(1+L6) -> 81427.045
A8: EBITDA margin (incl. overlay) | B8: =Historical!H44 -> 0.29580827 | C8: =Assumptions!B33+Assumptions!$B$28 -> 0.295 | D8: =Assumptions!C33+Assumptions!$B$28 -> 0.3 | E8: =Assumptions!D33+Assumptions!$B$28 -> 0.3 | F8: =Assumptions!E33+Assumptions!$B$28 -> 0.3 | G8: =Assumptions!F33+Assumptions!$B$28 -> 0.3 | H8: =Assumptions!G33+Assumptions!$B$28 -> 0.3 | I8: =Assumptions!H33+Assumptions!$B$28 -> 0.3 | J8: =Assumptions!I33+Assumptions!$B$28 -> 0.3 | ... L8: =Assumptions!K33+Assumptions!$B$28 -> 0.3
A9: EBITDA | B9: =Historical!H6 -> 9788 | C9: =C7*C8 -> 10834.993 | D9: =D7*D8 -> 12451.06 | E9: =E7*E8 -> 14069.698 | F9: =F7*F8 -> 15617.364 | G9: =G7*G8 -> 17179.101 | H9: =H7*H8 -> 18725.22 | I9: =I7*I8 -> 20223.237 | J9: =J7*J8 -> 21638.864 | ... L9: =L7*L8 -> 24428.114
A10: D&A | B10: =Historical!H9 -> 1355 | C10: =C7*Assumptions!B34 -> 1542.6092 | D10: =D7*Assumptions!C34 -> 1743.1484 | E10: =E7*Assumptions!D34 -> 1969.7577 | F10: =F7*Assumptions!E34 -> 2186.431 | G10: =G7*Assumptions!F34 -> 2405.0741 | H10: =H7*Assumptions!G34 -> 2621.5308 | I10: =I7*Assumptions!H34 -> 2831.2532 | J10: =J7*Assumptions!I34 -> 3029.441 | ... L10: =L7*Assumptions!K34 -> 3419.9359
A11: EBIT | B11: =B9-B10 -> 8433 | C11: =C9-C10 -> 9292.3839 | D11: =D9-D10 -> 10707.911 | E11: =E9-E10 -> 12099.94 | F11: =F9-F10 -> 13430.933 | G11: =G9-G10 -> 14774.027 | H11: =H9-H10 -> 16103.689 | I11: =I9-I10 -> 17391.984 | ... L11: =L9-L10 -> 21008.178
A12: Tax on EBIT | C12: =C11*Assumptions!B35 -> 2323.096 | D12: =D11*Assumptions!C35 -> 2676.9779 | E12: =E11*Assumptions!D35 -> 3024.985 | F12: =F11*Assumptions!E35 -> 3357.7333 | G12: =G11*Assumptions!F35 -> 3693.5067 | H12: =H11*Assumptions!G35 -> 4025.9223 | I12: =I11*Assumptions!H35 -> 4347.996 | J12: =J11*Assumptions!I35 -> 4652.3558 | ... L12: =L11*Assumptions!K35 -> 5252.0444
A13: NOPAT | C13: =C11-C12 -> 6969.2879 | D13: =D11-D12 -> 8030.9336 | E13: =E11-E12 -> 9074.9549 | F13: =F11-F12 -> 10073.2 | G13: =G11-G12 -> 11080.52 | H13: =H11-H12 -> 12077.767 | I13: =I11-I12 -> 13043.988 | J13: =J11-J12 -> 13957.067 | ... L13: =L11-L12 -> 15756.133
A14: Capex | B14: =Historical!H53 -> 2468 | C14: =C7*Assumptions!B36 -> 2754.6593 | D14: =D7*Assumptions!C36 -> 3112.765 | E14: =E7*Assumptions!D36 -> 3282.9294 | F14: =F7*Assumptions!E36 -> 3383.7623 | G14: =G7*Assumptions!F36 -> 3435.8202 | H14: =H7*Assumptions!G36 -> 3432.957 | I14: =I7*Assumptions!H36 -> 3707.5935 | J14: =J7*Assumptions!I36 -> 3967.1251 | ... L14: =L7*Assumptions!K36 -> 4478.4875
A15: Increase in NWC | C15: =(C7-B7)*Assumptions!B37 -> 363.979 | D15: =(D7-C7)*Assumptions!C37 -> 477.47427 | E15: =(E7-D7)*Assumptions!D37 -> 539.54593 | F15: =(F7-E7)*Assumptions!E37 -> 515.88891 | G15: =(G7-F7)*Assumptions!F37 -> 520.57881 | H15: =(H7-G7)*Assumptions!G37 -> 515.37302 | I15: =(I7-H7)*Assumptions!H37 -> 499.3392 | J15: =(J7-I7)*Assumptions!I37 -> 471.87554 | ... L15: =(L7-K7)*Assumptions!K37 -> 460.9078
A16: Free cash flow to firm (FCFF) | C16: =C13+C10-C14-C15 -> 5393.2588 | D16: =D13+D10-D14-D15 -> 6183.8427 | E16: =E13+E10-E14-E15 -> 7222.2372 | F16: =F13+F10-F14-F15 -> 8359.9798 | G16: =G13+G10-G14-G15 -> 9529.1951 | H16: =H13+H10-H14-H15 -> 10750.968 | I16: =I13+I10-I14-I15 -> 11668.309 | J16: =J13+J10-J14-J15 -> 12547.508 | ... L16: =L13+L10-L14-L15 -> 14236.674
A17: FCFF growth | D17: =D16/C16-1 -> 0.14658742 | E17: =E16/D16-1 -> 0.16792059 | F17: =F16/E16-1 -> 0.15753326 | G17: =G16/F16-1 -> 0.13985863 | H17: =H16/G16-1 -> 0.1282136 | I17: =I16/H16-1 -> 0.085326374 | J17: =J16/I16-1 -> 0.07534931 | K17: =K16/J16-1 -> 0.067686222 | L17: =L16/K16-1 -> 0.062692044
A19: Earnings bridge (for EPS and P/E cross-checks)
A20: Treasury / other income | B20: =Historical!H7 -> 3743 | C20: =B20*(1+Assumptions!B38) -> 3892.72 | D20: =C20*(1+Assumptions!C38) -> 4087.356 | E20: =D20*(1+Assumptions!D38) -> 4291.7238 | F20: =E20*(1+Assumptions!E38) -> 4506.31 | G20: =F20*(1+Assumptions!F38) -> 4731.6255 | H20: =G20*(1+Assumptions!G38) -> 4968.2068 | I20: =H20*(1+Assumptions!H38) -> 5216.6171 | J20: =I20*(1+Assumptions!I38) -> 5477.448 | ... L20: =K20*(1+Assumptions!K38) -> 6038.8864
A21: Profit before tax | B21: =Historical!H10 -> 12152 | C21: =C11+C20 -> 13185.104 | D21: =D11+D20 -> 14795.267 | E21: =E11+E20 -> 16391.664 | F21: =F11+F20 -> 17937.243 | G21: =G11+G20 -> 19505.652 | H21: =H11+H20 -> 21071.896 | I21: =I11+I20 -> 22608.601 | J21: =J11+J20 -> 24086.871 | ... L21: =L11+L20 -> 27047.064
A22: Net profit | B22: =Historical!H12 -> 9116 | C22: =C21*(1-Assumptions!B35) -> 9888.8279 | D22: =D21*(1-Assumptions!C35) -> 11096.451 | E22: =E21*(1-Assumptions!D35) -> 12293.748 | F22: =F21*(1-Assumptions!E35) -> 13452.932 | G22: =G21*(1-Assumptions!F35) -> 14629.239 | H22: =H21*(1-Assumptions!G35) -> 15803.922 | I22: =I21*(1-Assumptions!H35) -> 16956.451 | J22: =J21*(1-Assumptions!I35) -> 18065.153 | ... L22: =L21*(1-Assumptions!K35) -> 20285.298
A23: EPS (Rs) | B23: =Historical!H13 -> 136.3 | C23: =C22/Assumptions!$B$5 -> 147.85927 | D23: =D22/Assumptions!$B$5 -> 165.91583 | E23: =E22/Assumptions!$B$5 -> 183.818 | F23: =F22/Assumptions!$B$5 -> 201.15031 | G23: =G22/Assumptions!$B$5 -> 218.73862 | H23: =H22/Assumptions!$B$5 -> 236.30266 | I23: =I22/Assumptions!$B$5 -> 253.53545 | J23: =J22/Assumptions!$B$5 -> 270.11294 | ... L23: =L22/Assumptions!$B$5 -> 303.30888
A24: EPS growth | B24: =Historical!H46 -> 0.089909134 | C24: =C23/B23-1 -> 0.084807549 | D24: =D23/C23-1 -> 0.1221199 | E24: =E23/D23-1 -> 0.10789912 | F24: =F23/E23-1 -> 0.094290586 | G24: =G23/F23-1 -> 0.087438677 | H24: =H23/G23-1 -> 0.080296914 | I24: =I23/H23-1 -> 0.072926778 | J24: =J23/I23-1 -> 0.065385281 | ... L24: =L23/K23-1 -> 0.057750786
A25: DPS (Rs) | B25: =Assumptions!B10 -> 45 | C25: =C23*Assumptions!$B$29 -> 48.793559 | D25: =D23*Assumptions!$B$29 -> 54.752223 | E25: =E23*Assumptions!$B$29 -> 60.65994 | F25: =F23*Assumptions!$B$29 -> 66.379601 | G25: =G23*Assumptions!$B$29 -> 72.183746 | H25: =H23*Assumptions!$B$29 -> 77.979878 | I25: =I23*Assumptions!$B$29 -> 83.666699 | J25: =J23*Assumptions!$B$29 -> 89.137269 | ... L25: =L23*Assumptions!$B$29 -> 100.09193
A26: P/E at CMP (x) | B26: =Assumptions!$B$4/B23 -> 34.157007 | C26: =Assumptions!$B$4/C23 -> 31.486697 | D26: =Assumptions!$B$4/D23 -> 28.060011 | E26: =Assumptions!$B$4/E23 -> 25.327226 | F26: =Assumptions!$B$4/F23 -> 23.144881 | G26: =Assumptions!$B$4/G23 -> 21.28385 | H26: =Assumptions!$B$4/H23 -> 19.701852 | I26: =Assumptions!$B$4/I23 -> 18.362718 | ... L26: =Assumptions!$B$4/L23 -> 15.349369
A27: Other income % of PBT | B27: =B20/B21 -> 0.30801514 | C27: =C20/C21 -> 0.2952362 | D27: =D20/D21 -> 0.27626104 | E27: =E20/E21 -> 0.26182356 | F27: =F20/F21 -> 0.25122645 | G27: =G20/G21 -> 0.24257715 | H27: =H20/H21 -> 0.23577408 | I27: =I20/I21 -> 0.23073595 | ... L27: =L20/L21 -> 0.22327327

Sheet DCF
A1: Discounted Cash Flow - FCFF, 10-year explicit, mid-year convention
A2: Valued at 31-Mar-2026, rolled forward to 10-Oct-2026 at WACC. Green = link to another sheet.
C4: FY27E | D4: FY28E | E4: FY29E | F4: FY30E | G4: FY31E | H4: FY32E | I4: FY33E | J4: FY34E | K4: FY35E | L4: FY36E
A5: Discount period t (mid-year) | C5: =Forecast!C5-0.5 -> 0.5 | D5: =Forecast!D5-0.5 -> 1.5 | E5: =Forecast!E5-0.5 -> 2.5 | F5: =Forecast!F5-0.5 -> 3.5 | G5: =Forecast!G5-0.5 -> 4.5 | H5: =Forecast!H5-0.5 -> 5.5 | I5: =Forecast!I5-0.5 -> 6.5 | J5: =Forecast!J5-0.5 -> 7.5 | ... L5: =Forecast!L5-0.5 -> 9.5
A6: Discount factor | C6: =1/(1+$B$11)^C5 -> 0.94596754 | D6: =1/(1+$B$11)^D5 -> 0.84650339 | E6: =1/(1+$B$11)^E5 -> 0.75749744 | F6: =1/(1+$B$11)^F5 -> 0.67785006 | G6: =1/(1+$B$11)^G5 -> 0.60657723 | H6: =1/(1+$B$11)^H5 -> 0.54279842 | I6: =1/(1+$B$11)^I5 -> 0.48572566 | J6: =1/(1+$B$11)^J5 -> 0.43465383 | ... L6: =1/(1+$B$11)^L5 -> 0.34805546
A7: FCFF (Rs Cr) | C7: =Forecast!C16 -> 5393.2588 | D7: =Forecast!D16 -> 6183.8427 | E7: =Forecast!E16 -> 7222.2372 | F7: =Forecast!F16 -> 8359.9798 | G7: =Forecast!G16 -> 9529.1951 | H7: =Forecast!H16 -> 10750.968 | I7: =Forecast!I16 -> 11668.309 | J7: =Forecast!J16 -> 12547.508 | ... L7: =Forecast!L16 -> 14236.674
A8: PV of FCFF (Rs Cr) | C8: =C7*C6 -> 5101.8478 | D8: =D7*D6 -> 5234.6438 | E8: =E7*E6 -> 5470.8262 | F8: =F7*F6 -> 5666.8128 | G8: =G7*G6 -> 5780.1928 | H8: =H7*H6 -> 5835.6082 | I8: =I7*I6 -> 5667.5969 | J8: =J7*J6 -> 5453.8223 | ... L8: =L7*L6 -> 4955.152
A10: Valuation
A11: WACC used | B11: =Assumptions!B22 -> 0.1175
A12: Terminal growth (g) | B12: =Assumptions!B23 -> 0.05
A13: Sum of PV (FY27E-FY36E) | B13: =SUM(C8:L8) -> 54377.215
A14: Terminal value at FY36E (Rs Cr) | B14: =L7*(1+B12)/(B11-B12) -> 221459.37
A15: PV of terminal value (Rs Cr) | B15: =B14/(1+B11)^L5 -> 77080.143
A16: Enterprise value (Rs Cr) | B16: =B13+B15 -> 131457.36
A17: Terminal value % of EV | B17: =B15/B16 -> 0.58635092
A18: Cash credit % applied to deposits + investments | B18: =Assumptions!B24 -> 0.5
A19: Cash & investments credited (Rs Cr) | B19: =B18*(Assumptions!B7+Assumptions!B8) -> 22169.5
A20: Less: borrowings (Rs Cr) | B20: =Assumptions!B9 -> 66
A21: Equity value at 31-Mar-2026 (Rs Cr) | B21: =B16+B19-B20 -> 153560.86
A22: Per share at 31-Mar-2026 (Rs) | B22: =B21/Assumptions!B5 -> 2296.0655
A23: Roll-forward factor to 10-Oct-2026 | B23: =(1+B11)^Assumptions!B13 -> 1.0605025
A24: DCF value per share today (Rs) | B24: =B22*B23 -> 2434.9832
A25: vs CMP | B25: =B24/Assumptions!B4-1 -> -0.47697757
A26: DCF EV / FY27E EBITDA (x) | B26: =B16/Forecast!C9 -> 12.132667
A27: Market EV (mcap - deposits - investments + debt) (Rs Cr) | B27: =Assumptions!B6-Assumptions!B7-Assumptions!B8+Assumptions!B9 -> 267093.53
A28: Market EV / FY27E EBITDA (x) | B28: =B27/Forecast!C9 -> 24.651011
A29: Market EV / FY26A EBITDA (x) | B29: =B27/Forecast!B9 -> 27.287855
A30: Market-implied P/E on FY27E EPS (x) | B30: =Assumptions!B4/Forecast!C23 -> 31.486697
A33: Sensitivity: DCF value per share today (Rs) - WACC (rows) x terminal growth (columns)
A34: WACC \ g | C34: 0.03 | D34: 0.04 | E34: 0.05 | F34: 0.06 | G34: 0.07
A35: =$B$11+(-0.02) -> 0.0975 | C35: =(SUMPRODUCT($C$7:$L$7/(1+$A35)^$C$5:$L$5)+$L$7*(1+C$34)/($A35-C$34)/(1+$A35)^$L$5+$B$19-$B$20)/Assumptions!$B$5*(1+$A35)^Assumptions!$B$13 -> 2692.7175 | D35: =(SUMPRODUCT($C$7:$L$7/(1+$A35)^$C$5:$L$5)+$L$7*(1+D$34)/($A35-D$34)/(1+$A35)^$L$5+$B$19-$B$20)/Assumptions!$B$5*(1+$A35)^Assumptions!$B$13 -> 2953.9738 | E35: =(SUMPRODUCT($C$7:$L$7/(1+$A35)^$C$5:$L$5)+$L$7*(1+E$34)/($A35-E$34)/(1+$A35)^$L$5+$B$19-$B$20)/Assumptions!$B$5*(1+$A35)^Assumptions!$B$13 -> 3325.2327 | F35: =(SUMPRODUCT($C$7:$L$7/(1+$A35)^$C$5:$L$5)+$L$7*(1+F$34)/($A35-F$34)/(1+$A35)^$L$5+$B$19-$B$20)/Assumptions!$B$5*(1+$A35)^Assumptions!$B$13 -> 3894.4964 | G35: =(SUMPRODUCT($C$7:$L$7/(1+$A35)^$C$5:$L$5)+$L$7*(1+G$34)/($A35-G$34)/(1+$A35)^$L$5+$B$19-$B$20)/Assumptions!$B$5*(1+$A35)^Assumptions!$B$13 -> 4877.7701
A36: =$B$11+(-0.01) -> 0.1075 | C36: =(SUMPRODUCT($C$7:$L$7/(1+$A36)^$C$5:$L$5)+$L$7*(1+C$34)/($A36-C$34)/(1+$A36)^$L$5+$B$19-$B$20)/Assumptions!$B$5*(1+$A36)^Assumptions!$B$13 -> 2378.5677 | D36: =(SUMPRODUCT($C$7:$L$7/(1+$A36)^$C$5:$L$5)+$L$7*(1+D$34)/($A36-D$34)/(1+$A36)^$L$5+$B$19-$B$20)/Assumptions!$B$5*(1+$A36)^Assumptions!$B$13 -> 2558.883 | E36: =(SUMPRODUCT($C$7:$L$7/(1+$A36)^$C$5:$L$5)+$L$7*(1+E$34)/($A36-E$34)/(1+$A36)^$L$5+$B$19-$B$20)/Assumptions!$B$5*(1+$A36)^Assumptions!$B$13 -> 2801.9166 | F36: =(SUMPRODUCT($C$7:$L$7/(1+$A36)^$C$5:$L$5)+$L$7*(1+F$34)/($A36-F$34)/(1+$A36)^$L$5+$B$19-$B$20)/Assumptions!$B$5*(1+$A36)^Assumptions!$B$13 -> 3147.2803 | G36: =(SUMPRODUCT($C$7:$L$7/(1+$A36)^$C$5:$L$5)+$L$7*(1+G$34)/($A36-G$34)/(1+$A36)^$L$5+$B$19-$B$20)/Assumptions!$B$5*(1+$A36)^Assumptions!$B$13 -> 3676.8378
A37: =$B$11+(0) -> 0.1175 | C37: =(SUMPRODUCT($C$7:$L$7/(1+$A37)^$C$5:$L$5)+$L$7*(1+C$34)/($A37-C$34)/(1+$A37)^$L$5+$B$19-$B$20)/Assumptions!$B$5*(1+$A37)^Assumptions!$B$13 -> 2137.6536 | D37: =(SUMPRODUCT($C$7:$L$7/(1+$A37)^$C$5:$L$5)+$L$7*(1+D$34)/($A37-D$34)/(1+$A37)^$L$5+$B$19-$B$20)/Assumptions!$B$5*(1+$A37)^Assumptions!$B$13 -> 2267.1359 | E37: =(SUMPRODUCT($C$7:$L$7/(1+$A37)^$C$5:$L$5)+$L$7*(1+E$34)/($A37-E$34)/(1+$A37)^$L$5+$B$19-$B$20)/Assumptions!$B$5*(1+$A37)^Assumptions!$B$13 -> 2434.9832 | F37: =(SUMPRODUCT($C$7:$L$7/(1+$A37)^$C$5:$L$5)+$L$7*(1+F$34)/($A37-F$34)/(1+$A37)^$L$5+$B$19-$B$20)/Assumptions!$B$5*(1+$A37)^Assumptions!$B$13 -> 2661.2123 | G37: =(SUMPRODUCT($C$7:$L$7/(1+$A37)^$C$5:$L$5)+$L$7*(1+G$34)/($A37-G$34)/(1+$A37)^$L$5+$B$19-$B$20)/Assumptions!$B$5*(1+$A37)^Assumptions!$B$13 -> 2982.6956
A38: =$B$11+(0.01) -> 0.1275 | C38: =(SUMPRODUCT($C$7:$L$7/(1+$A38)^$C$5:$L$5)+$L$7*(1+C$34)/($A38-C$34)/(1+$A38)^$L$5+$B$19-$B$20)/Assumptions!$B$5*(1+$A38)^Assumptions!$B$13 -> 1947.3785 | D38: =(SUMPRODUCT($C$7:$L$7/(1+$A38)^$C$5:$L$5)+$L$7*(1+D$34)/($A38-D$34)/(1+$A38)^$L$5+$B$19-$B$20)/Assumptions!$B$5*(1+$A38)^Assumptions!$B$13 -> 2043.2449 | E38: =(SUMPRODUCT($C$7:$L$7/(1+$A38)^$C$5:$L$5)+$L$7*(1+E$34)/($A38-E$34)/(1+$A38)^$L$5+$B$19-$B$20)/Assumptions!$B$5*(1+$A38)^Assumptions!$B$13 -> 2163.851 | F38: =(SUMPRODUCT($C$7:$L$7/(1+$A38)^$C$5:$L$5)+$L$7*(1+F$34)/($A38-F$34)/(1+$A38)^$L$5+$B$19-$B$20)/Assumptions!$B$5*(1+$A38)^Assumptions!$B$13 -> 2320.1923 | G38: =(SUMPRODUCT($C$7:$L$7/(1+$A38)^$C$5:$L$5)+$L$7*(1+G$34)/($A38-G$34)/(1+$A38)^$L$5+$B$19-$B$20)/Assumptions!$B$5*(1+$A38)^Assumptions!$B$13 -> 2530.9132
A39: =$B$11+(0.02) -> 0.1375 | C39: =(SUMPRODUCT($C$7:$L$7/(1+$A39)^$C$5:$L$5)+$L$7*(1+C$34)/($A39-C$34)/(1+$A39)^$L$5+$B$19-$B$20)/Assumptions!$B$5*(1+$A39)^Assumptions!$B$13 -> 1793.5578 | D39: =(SUMPRODUCT($C$7:$L$7/(1+$A39)^$C$5:$L$5)+$L$7*(1+D$34)/($A39-D$34)/(1+$A39)^$L$5+$B$19-$B$20)/Assumptions!$B$5*(1+$A39)^Assumptions!$B$13 -> 1866.2851 | E39: =(SUMPRODUCT($C$7:$L$7/(1+$A39)^$C$5:$L$5)+$L$7*(1+E$34)/($A39-E$34)/(1+$A39)^$L$5+$B$19-$B$20)/Assumptions!$B$5*(1+$A39)^Assumptions!$B$13 -> 1955.6358 | F39: =(SUMPRODUCT($C$7:$L$7/(1+$A39)^$C$5:$L$5)+$L$7*(1+F$34)/($A39-F$34)/(1+$A39)^$L$5+$B$19-$B$20)/Assumptions!$B$5*(1+$A39)^Assumptions!$B$13 -> 2068.0448 | G39: =(SUMPRODUCT($C$7:$L$7/(1+$A39)^$C$5:$L$5)+$L$7*(1+G$34)/($A39-G$34)/(1+$A39)^$L$5+$B$19-$B$20)/Assumptions!$B$5*(1+$A39)^Assumptions!$B$13 -> 2213.76
A40: Base case highlighted. Grid recomputes WACC, g and the roll-forward consistently with the main DCF.
A42: Sensitivity: DCF value per share today (Rs) - cash credit % (base WACC, g)
A43: Cash credit | C43: 0 | D43: 0.25 | E43: 0.5 | F43: 0.75 | G43: 1
A44: Value per share (Rs) | C44: =($B$16+C43*(Assumptions!$B$7+Assumptions!$B$8)-$B$20)/Assumptions!$B$5*$B$23 -> 2083.446 | D44: =($B$16+D43*(Assumptions!$B$7+Assumptions!$B$8)-$B$20)/Assumptions!$B$5*$B$23 -> 2259.2146 | E44: =($B$16+E43*(Assumptions!$B$7+Assumptions!$B$8)-$B$20)/Assumptions!$B$5*$B$23 -> 2434.9832 | F44: =($B$16+F43*(Assumptions!$B$7+Assumptions!$B$8)-$B$20)/Assumptions!$B$5*$B$23 -> 2610.7518 | G44: =($B$16+G43*(Assumptions!$B$7+Assumptions!$B$8)-$B$20)/Assumptions!$B$5*$B$23 -> 2786.5205
A47: Reverse DCF: what the market is pricing
...

Sheet Comps
A1: Relative Valuation - Indian defence PSU / capital-goods peers
A2: Peer multiples: Screener.in / Value Research snapshots, 1-9 Oct 2026 (TTM). Net margin = TTM PAT / TTM revenue. Peer figures are aggregator-sourced; verify before trading.
A4: Company | B4: Mkt cap (Rs Cr) | C4: P/E (x) | D4: P/B (x) | E4: ROE | F4: Net margin | G4: P/B per unit ROE
A5: Bharat Electronics (BEL) | B5: 269110 | C5: 43.8 | D5: 11.2 | E5: 0.274 | F5: 0.214 | G5: =D5/E5/100 -> 0.40875912
A6: Mazagon Dock (MAZDOCK) | B6: 83453 | C6: 29.2 | D6: 8.1 | E6: 0.306 | F6: 0.186 | G6: =D6/E6/100 -> 0.26470588
A7: Garden Reach (GRSE) | B7: 24168 | C7: 30.2 | D7: 8.6 | E7: 0.325 | F7: 0.103 | G7: =D7/E7/100 -> 0.26461538
A8: Cochin Shipyard (CSL) | B8: 33897 | C8: 49.8 | D8: 5.6 | E8: 0.118 | F8: 0.124 | G8: =D8/E8/100 -> 0.47457627
A9: Median - included peers | C9: =MEDIAN(C5:C8) -> 37 | D9: =MEDIAN(D5:D8) -> 8.35 | E9: =MEDIAN(E5:E8) -> 0.29 | F9: =MEDIAN(F5:F8) -> 0.155 | G9: =MEDIAN(G5:G8) -> 0.3367325
A10: Mean - included peers | C10: =AVERAGE(C5:C8) -> 38.25 | D10: =AVERAGE(D5:D8) -> 8.375 | E10: =AVERAGE(E5:E8) -> 0.25575 | F10: =AVERAGE(F5:F8) -> 0.15675 | G10: =AVERAGE(G5:G8) -> 0.35316417
A12: Excluded as outlier: Bharat Dynamics (BDL) | B12: 39308 | C12: 75.5 | D12: 9.3 | E12: 0.102 | F12: 0.188 | G12: =D12/E12/100 -> 0.91176471 | H12: TTM revenue -19% and OPM ~13%; P/E inflated by depressed earnings
A14: HAL (at CMP) | B14: =Assumptions!B6 -> 311366.53 | C14: =Assumptions!B4/C17 -> 33.40221 | D14: =Assumptions!B4/C18 -> 7.5867188 | E14: =Historical!H50 -> 0.23982531 | F14: =C16/C19 -> 0.27589167 | G14: =D14/E14/100 -> 0.31634354
A16: HAL TTM net profit (Rs Cr) | C16: 9321
A17: HAL TTM EPS (Rs) | C17: 139.38
A18: HAL book value per share (Rs) | C18: =Historical!H49/Assumptions!B5 -> 613.65132
A19: HAL TTM revenue (Rs Cr) | C19: 33785
A21: Implied HAL value per share (Rs)
A22: (a) Median peer P/E x HAL TTM EPS | C22: =C9*C17 -> 5157.06
A23: (b) Median peer (P/B per unit ROE) x HAL ROE x HAL BVPS | C23: =G9*E14*100*C18 -> 4955.6626
A24: Comps value (simple average of a, b) | C24: =AVERAGE(C22:C23) -> 5056.3613
A25: vs CMP | C25: =C24/Assumptions!B4-1 -> 0.086081557
A27: Cross-checks
A28: HAL P/E on core earnings (ex treasury income, at CMP) | C28: =Assumptions!B6/((Forecast!B9-Forecast!B10)*(1-Assumptions!B35)) -> 49.229855
A29: Value if BDL included: median P/E x HAL TTM EPS | C29: =MEDIAN(C5:C8,C12)*C17 -> 6104.844
A30: Value at mean included-peer P/E x HAL TTM EPS | C30: =C10*C17 -> 5331.285

Sheet Valuation
A1: Valuation Summary, Price Target and Rating
A2: Weights and rating bands are stated inputs (yellow). Change them to see the effect; the weight sensitivity table below shows the full range.
A4: Methodology | B4: Value / share (Rs) | C4: vs CMP | D4: Weight
A5: DCF - base case (WACC, g per Assumptions) | B5: =DCF!B24 -> 2434.9832 | C5: =B5/Assumptions!$B$4-1 -> -0.47697757 | D5: 0.5
A6: Comps - avg of peer P/E and ROE-adjusted P/B | B6: =Comps!C24 -> 5056.3613 | C6: =B6/Assumptions!$B$4-1 -> 0.086081557 | D6: =1-D5 -> 0.5
A7: Blended fair value today (Rs) | B7: =B5*D5+B6*D6 -> 3745.6723 | C7: =B7/Assumptions!$B$4-1 -> -0.19544801
A8: 12-month roll-forward factor = 1 + Ke - dividend yield | B8: =1+Assumptions!B19-Assumptions!B11 -> 1.1078342
A9: 12-month target price (Rs, rounded to Rs 10) | B9: =ROUND(B7*B8/10,0)*10 -> 4150 | C9: =B9/Assumptions!B4-1 -> -0.1086004
A10: CMP (Rs) | B10: =Assumptions!B4 -> 4655.6
A12: Rating bands (12M expected price return vs CMP)
A13: BUY if upside >= | B13: 0.15
A14: REDUCE if upside <= | B14: -0.15
A15: Rating | B15: =IF(C9>=B13,"BUY",IF(C9<=B14,"REDUCE","HOLD")) -> HOLD
A17: Weight sensitivity - 12M target price vs DCF weight
A18: DCF weight | B18: Fair value today | C18: 12M target (Rs) | D18: vs CMP | E18: Rating
A19: 0 | B19: =$B$5*A19+$B$6*(1-A19) -> 5056.3613 | C19: =ROUND(B19*$B$8/10,0)*10 -> 5600 | D19: =C19/Assumptions!$B$4-1 -> 0.20285248 | E19: =IF(D19>=$B$13,"BUY",IF(D19<=$B$14,"REDUCE","HOLD")) -> BUY
A20: 0.25 | B20: =$B$5*A20+$B$6*(1-A20) -> 4401.0168 | C20: =ROUND(B20*$B$8/10,0)*10 -> 4880 | D20: =C20/Assumptions!$B$4-1 -> 0.048200017 | E20: =IF(D20>=$B$13,"BUY",IF(D20<=$B$14,"REDUCE","HOLD")) -> HOLD
A21: 0.4 | B21: =$B$5*A21+$B$6*(1-A21) -> 4007.8101 | C21: =ROUND(B21*$B$8/10,0)*10 -> 4440 | D21: =C21/Assumptions!$B$4-1 -> -0.04630982 | E21: =IF(D21>=$B$13,"BUY",IF(D21<=$B$14,"REDUCE","HOLD")) -> HOLD
A22: 0.5 | B22: =$B$5*A22+$B$6*(1-A22) -> 3745.6723 | C22: =ROUND(B22*$B$8/10,0)*10 -> 4150 | D22: =C22/Assumptions!$B$4-1 -> -0.1086004 | E22: =IF(D22>=$B$13,"BUY",IF(D22<=$B$14,"REDUCE","HOLD")) -> HOLD
A23: 0.65 | B23: =$B$5*A23+$B$6*(1-A23) -> 3352.4656 | C23: =ROUND(B23*$B$8/10,0)*10 -> 3710 | D23: =C23/Assumptions!$B$4-1 -> -0.20311023 | E23: =IF(D23>=$B$13,"BUY",IF(D23<=$B$14,"REDUCE","HOLD")) -> REDUCE
A24: 0.75 | B24: =$B$5*A24+$B$6*(1-A24) -> 3090.3277 | C24: =ROUND(B24*$B$8/10,0)*10 -> 3420 | D24: =C24/Assumptions!$B$4-1 -> -0.26540081 | E24: =IF(D24>=$B$13,"BUY",IF(D24<=$B$14,"REDUCE","HOLD")) -> REDUCE
A25: 1 | B25: =$B$5*A25+$B$6*(1-A25) -> 2434.9832 | C25: =ROUND(B25*$B$8/10,0)*10 -> 2700 | D25: =C25/Assumptions!$B$4-1 -> -0.42005327 | E25: =IF(D25>=$B$13,"BUY",IF(D25<=$B$14,"REDUCE","HOLD")) -> REDUCE
A27: Cross-check: what the broker community says
A28: Anand Rathi target (BUY, Jul-2026, via TradeBrains) | B28: 5431
A29: TradingView analyst range (low / high) | B29: 3200 | C29: 6800

Sheet MonteCarlo
A1: Monte Carlo DCF - static output of hal_monte_carlo.py
A2: 20,000 simulations, seed 42. Values below are pasted outputs (blue) - re-run the script to refresh. Not formula-driven.
A4: Statistic | B4: Value (Rs/share)
A5: Base-case DCF (point estimate) | B5: 2434.9832
A6: Median of 20,000 simulations | B6: 2448.1898
A7: Mean | B7: 2481.8324
A8: P5 | B8: 1787.5208
A9: P10 | B9: 1918.7829
A10: P25 | B10: 2156.8387
A11: P50 | B11: 2448.1898
A12: P75 | B12: 2766.7243
A13: P90 | B13: 3081.8235
A14: P95 | B14: 3298.602
A16: CMP (Rs) | B16: =Assumptions!B4 -> 4655.6
A17: P(intrinsic value > CMP) | B17: 0.00015
A18: P(intrinsic value > Rs 3,000) | B18: 0.12925
A19: P(intrinsic value < Rs 2,000) | B19: 0.14435
A22: Distributions sampled
A23: WACC | B23: Normal(11.75%, sd 0.8pp), clipped 8%-15%
A24: Terminal growth | B24: Normal(5.0%, sd 0.5pp), clipped 3.5%-6.5%, WACC-g >= 3.5pp
A25: Revenue growth shift FY27-31 | B25: Normal(0, sd 2.5pp) added to each year
A26: EBITDA margin shift | B26: Normal(0, sd 1.8pp) all years
A27: Capex scale | B27: Lognormal(0, 0.12) multiplier
A28: NWC % of incremental revenue | B28: Uniform(0%, 20%)
A29: Cash credit % | B29: Uniform(0%, 100%)
A31: Driver correlation with value/share
A32: WACC | B32: -0.57753369
A33: Revenue growth shift (FY27-31) | B33: 0.46146407
A34: Cash credit % | B34: 0.43258989
A35: EBITDA margin shift | B35: 0.37372474
A36: Terminal growth (g) | B36: 0.22043654
A37: Capex scale | B37: -0.19059997
A38: NWC % of incr. revenue | B38: -0.11301201

Sheet Scenarios
A1: Scenario snapshot (Python-run; reproduce by typing overlays into Assumptions!B21, B24, B27, B28)
A2: Static values (blue). Overlays: growth overlay applies FY27E-FY31E; margin overlay all years.
A4: Scenario | B4: Growth overlay | C4: Margin overlay | D4: WACC overlay | E4: Cash credit | F4: DCF value/share (Rs) | G4: vs CMP
A5: Bear: Tejas slips again, margins <guidance | B5: -0.04 | C5: -0.02 | D5: 0.005 | E5: 0.25 | F5: 1680.1 | G5: =F5/Assumptions!$B$4-1 -> -0.63912278
A6: Base | B6: 0 | C6: 0 | D6: 0 | E6: 0.5 | F6: 2435 | G6: =F6/Assumptions!$B$4-1 -> -0.47697397
A7: Bull: guidance met + order inflow upside | B7: 0.03 | C7: 0.01 | D7: -0.005 | E7: 0.75 | F7: 3179 | G7: =F7/Assumptions!$B$4-1 -> -0.31716642
A9: What you need to believe to justify the CMP (each holding all else at base)
A10: Cost of equity needed (vs 11.75% assumed) | B10: 0.083
A11: Terminal growth needed at 11.75% WACC (vs 5.0%) | B11: 0.0926
A12: 10-yr revenue CAGR needed at 11.75% WACC (vs 9.4% base) | B12: 0.1994
A13: Steady-state EBITDA margin needed at 11.75% WACC (vs 30%) | B13: 0.5417

Sheet Notes
A1: Sources, method notes and limitations
A3: 1. Historical financials: Screener.in consolidated P&L, balance sheet, cash flow and ratios for HAL (retrieved 10-Oct-2026), derived from company filings.
A4: 2. Price: NSE close 9-Oct-2026 Rs 4,655.60. 52-week range Rs 3,479.10 - Rs 5,149.90. Market cap ~Rs 3.11 lakh Cr.
A5: 3. Order book Rs 2,54,538 Cr, fresh orders Rs 97,028 Cr, FY26 revenue Rs 33,050 Cr (call basis; Rs 33,089 Cr consolidated per Screener), capex Rs 2,386 Cr, R&D Rs 2,794 Cr: HAL Q4 FY26 earnings call (May 2026).
A6: 4. FY27 guidance: revenue +10-12%, EBITDA margin 30-31%; Q1 FY27 (Aug-2026): revenue +14%, EBITDA margin 27.7%.
A7: 5. Customer advances: other non-current liabilities Rs 44,689 Cr vs bank deposits Rs 42,425 Cr (FY26 standalone balance sheet, per Sahi analysis of the annual report).
A8: 6. Peer multiples: Screener.in (BEL, BDL, 9-Oct-2026) and Value Research peer table (MAZDOCK, CSL, GRSE, 1-Oct-2026). Aggregator data; small differences vs exchange data are possible.
A9: 7. Risk-free rate: India 10Y G-Sec ~7.0-7.2% (Trading Economics, late Sep 2026). Beta 0.95 (TradingView).
A10: 8. Method: 10-year FCFF DCF (ex treasury income), mid-year discounting, Gordon terminal value; equity bridge credits only a stated % of cash/deposits because they are largely customer-advance funded.
A11: 9. Key judgement 1: cash credit 50% (range 0-100% shown in DCF sheet). Key judgement 2: DCF/comps weights 50/50 (full range shown in Valuation sheet).
A12: 10. Limitations: consolidated vs standalone differences; no segment build; Monte Carlo and scenarios are static outputs of Python; peers are few and richly valued; no forward consensus data.
